Traceback (most recent call last):
  File "/home/shahzar/.local/lib/python3.8/site-packages/jupyter_cache/executors/utils.py", line 51, in single_nb_execution
    executenb(
  File "/home/shahzar/.local/lib/python3.8/site-packages/nbclient/client.py", line 1263, in execute
    return NotebookClient(nb=nb, resources=resources, km=km, **kwargs).execute()
  File "/home/shahzar/.local/lib/python3.8/site-packages/nbclient/util.py", line 85, in wrapped
    return just_run(coro(*args, **kwargs))
  File "/home/shahzar/.local/lib/python3.8/site-packages/nbclient/util.py", line 60, in just_run
    return loop.run_until_complete(coro)
  File "/usr/lib/python3.8/asyncio/base_events.py", line 616, in run_until_complete
    return future.result()
  File "/home/shahzar/.local/lib/python3.8/site-packages/nbclient/client.py", line 701, in async_execute
    await self.async_execute_cell(
  File "/home/shahzar/.local/lib/python3.8/site-packages/nbclient/client.py", line 1019, in async_execute_cell
    await self._check_raise_for_error(cell, cell_index, exec_reply)
  File "/home/shahzar/.local/lib/python3.8/site-packages/nbclient/client.py", line 913, in _check_raise_for_error
    raise CellExecutionError.from_cell_and_msg(cell, exec_reply_content)
nbclient.exceptions.CellExecutionError: An error occurred while executing the following cell:
------------------
# NO CODE

from datascience import *
from prob140 import *
%matplotlib inline
import matplotlib.pyplot as plt
plt.style.use('fivethirtyeight')
import numpy as np
------------------

[0;31m---------------------------------------------------------------------------[0m
[0;31mModuleNotFoundError[0m                       Traceback (most recent call last)
Input [0;32mIn [1][0m, in [0;36m<cell line: 3>[0;34m()[0m
[1;32m      1[0m [38;5;66;03m# NO CODE[39;00m
[0;32m----> 3[0m [38;5;28;01mfrom[39;00m [38;5;21;01mdatascience[39;00m [38;5;28;01mimport[39;00m [38;5;241m*[39m
[1;32m      4[0m [38;5;28;01mfrom[39;00m [38;5;21;01mprob140[39;00m [38;5;28;01mimport[39;00m [38;5;241m*[39m
[1;32m      5[0m get_ipython()[38;5;241m.[39mrun_line_magic([38;5;124m'[39m[38;5;124mmatplotlib[39m[38;5;124m'[39m, [38;5;124m'[39m[38;5;124minline[39m[38;5;124m'[39m)

[0;31mModuleNotFoundError[0m: No module named 'datascience'
ModuleNotFoundError: No module named 'datascience'

